Workbook

Sheet Dados
B2: Informações Relativas às Fábricas
B3: Fábricas | C3: CP (kL) | D3: CI (mil€/kL) | E3: CPE (kL) | F3: CIE (mil€/kL) | J3: CP = Capacidade de Produção
B4: Nocal | C4: 200000 | D4: 42.5 | E4: =0.3*C4 -> 60000 | F4: =1.1*D4 -> 46.75 | J4: CI = Custo Industrial
B5: Catumbela | C5: 50000 | D5: 45 | E5: =0.3*C5 -> 15000 | F5: =1.1*D5 -> 49.5 | J5: CPE = Capacidade de Produção Extraordinária
B6: Cobeje | C6: 125000 | D6: 47.5 | E6: =0.3*C6 -> 37500 | F6: =1.1*D6 -> 52.25 | J6: CIE = Custo Industrial Extraordinário
B7: Nocebo | C7: 33500 | D7: 50 | E7: =0.3*C7 -> 10050 | F7: =1.1*D7 -> 55
B9: Informações Relativas ao Transporte
B10: Armazéns | C10: Luanda | D10: Cabinda | E10: Lobito | F10: Huambo | G10: Namibe | H10: Malange | J10: Obs: Valores em mil€/kL
B11: =B4 -> Nocal | C11: 0.1 | D11: 0.6 | E11: 0.25 | F11: 0.8 | G11: 1.2 | H11: 0.55
B12: =B5 -> Catumbela | C12: 0.5 | D12: 0.8 | E12: 0.05 | F12: 0.2 | G12: 0.5 | H12: 0.75
B13: =B6 -> Cobeje | C13: 0.4 | D13: 0.5 | E13: 0.7 | F13: 0.45 | G13: 1 | H13: 0.2
B14: =B7 -> Nocebo | C14: 0.7 | D14: 0.75 | E14: 0.5 | F14: 0.85 | G14: 0.6 | H14: 0.9
B16: Informações Relativas à Distribuição e Venda
C17: {=C10:H10} -> Luanda | D17: Cabinda | E17: Lobito | F17: Huambo | G17: Namibe | H17: Malange | J17: QP = Quantidade Procurada
B18: QP (kL) | C18: 245000 | D18: 30000 | E18: 58387 | F18: 58656 | G18: 25000 | H18: 38700
B20: Outras Informações
B21: Fábrica | C21: Produzido | E21: Armazém | F21: Transportado
B22: =B5 -> Catumbela | C22: >= | D22: 5000 | E22: =G10 -> Namibe | F22: >= | G22: 5000
E23: =D10 -> Cabinda | F23: = | G23: ?
B24: =B4 -> Nocal | C24: >= | D24: 175000 | E24: =E10 -> Lobito
B25: =B7 -> Nocebo | C25: >= | D25: 10000 | E25: =F10 -> Huambo | F25: >= | G25: 10000

Sheet Variáveis e Restrições
B2: FO | D2: Min(Z) = 42,50x1 + 45,00x2 + 47,50x3 + 50,00x4 + 46,75x5 + 49,50x6 + 52,25x7 + 55,00x8 + 0,10x1,1 + 0,6x1,2 + 0,25x1,3 + 0,8x1,4 + 1,2x1,5 + 0,55x1,6 +0,5x2,1 + 0,8x2,2 + 0,05x2,3 + 0,2x2,4 +0,5x2,5 + 0,75x2,6 + 0,4x3,1 + 0,5x3,2 + 0,7x3,3 + 0,45x3,4 + 1,00x3,5 + 0,2x3,6 + 0,7x4,1 + 0,75x4,2 + 0,5x4,3 + 0,85x4,4 + 0,6x4,5 + 0,9x4,6
F4: Restrições Relativas às Fábricas
F5: Variável | G5: Sinal | H5: LDR | J5: LDR = Lado Direito da Restrição
B6: Variáveis Relativas às Fábricas | F6: x1 | G6: <= | H6: =Dados!C4 -> 200000
B7: Fábricas | C7: CP (kL) | D7: CPE (kL) | F7: x2 | G7: <= | H7: =Dados!C5 -> 50000
B8: Nocal | C8: x1 | D8: x5 | F8: x3 | G8: <= | H8: =Dados!C6 -> 125000
B9: Catumbela | C9: x2 | D9: x6 | F9: x4 | G9: <= | H9: =Dados!C7 -> 33500
B10: Cobeje | C10: x3 | D10: x7 | F10: x5 | G10: <= | H10: =Dados!E4 -> 60000
B11: Nocebo | C11: x4 | D11: x8 | F11: x6 | G11: <= | H11: =Dados!E5 -> 15000
F12: x7 | G12: <= | H12: =Dados!E6 -> 37500
F13: x8 | G13: <= | H13: =Dados!E7 -> 10050
J15: Restrições Relativas à Distribuição e Venda
B16: Variáveis Relativas ao Transporte | J16: Variáveis | K16: Sinal | L16: LDR | N16: Restrições Relativas à Produção e aos Transportes
B17: Armazéns | C17: Luanda | D17: Cabinda | E17: Lobito | F17: Huambo | G17: Namibe | H17: Malange | J17: x1,1+x2,1+x3,1+x4,1 | K17: >= | L17: =Dados!C18 -> 245000 | N17: Variáveis | O17: Sinal | P17: LDR
B18: =B8 -> Nocal | C18: x1,1 | D18: x1,2 | E18: x1,3 | F18: x1,4 | G18: x1,5 | H18: x1,6 | J18: x1,2+x2,2+x3,2+x4,2 | K18: >= | L18: =Dados!D18 -> 30000 | N18: x1,1+x1,2+x1,3+x1,4+x1,5+x1,6 | O18: = | P18: x1+x5
B19: =B9 -> Catumbela | C19: x2,1 | D19: x2,2 | E19: x2,3 | F19: x2,4 | G19: x2,5 | H19: x2,6 | J19: x1,3+x2,3+x3,3+x4,3 | K19: >= | L19: =Dados!E18 -> 58387 | N19: x2,1+x2,2+x2,3+x2,4+x2,5+x2,6 | O19: = | P19: x2+x6
B20: =B10 -> Cobeje | C20: x3,1 | D20: x3,2 | E20: x3,3 | F20: x3,4 | G20: x3,5 | H20: x3,6 | J20: x1,4+x2,4+x3,4+x4,4 | K20: >= | L20: =Dados!F18 -> 58656 | N20: x3,1+x3,2+x3,3+x3,4+x3,5+x3,6 | O20: = | P20: x3+x7
B21: =B11 -> Nocebo | C21: x4,1 | D21: x4,2 | E21: x4,3 | F21: x4,4 | G21: x4,5 | H21: x4,6 | J21: x1,5+x2,5+x3,5+x4,5 | K21: >= | L21: =Dados!G18 -> 25000 | N21: x4,1+x4,2+x4,3+x4,4+x4,5+x4,6 | O21: = | P21: x4+x8
J22: x1,6+x2,6+x3,6+x4,6 | K22: >= | L22: =Dados!H18 -> 38700
D24: Restrições Relativas às Outras Informações
D25: Variável | E25: Sinal | F25: LDR
D26: x2+x6 | E26: >= | F26: =Dados!D22 -> 5000
D27: x2,5 | E27: >= | F27: 5000
D28: x2,2 | E28: = | F28: x1,3
D29: x1+x5 | E29: >= | F29: =Dados!D24 -> 175000
D30: x4+x8 | E30: >= | F30: =Dados!D25 -> 10000
D31: x4,4 | E31: >= | F31: 10000

Sheet Modelo
A1: Variável | B1: x1 | C1: x2 | D1: x3 | E1: x4 | F1: x5 | G1: x6 | H1: x7 | I1: x8 | J1: x1,1 | K1: x1,2 | L1: x1,3 | M1: x1,4 | N1: x1,5 | O1: x1,6 | P1: x2,1 | Q1: x2,2 | R1: x2,3 | S1: x2,4 | T1: x2,5 | U1: x2,6 | V1: x3,1 | W1: x3,2 | X1: x3,3 | Y1: x3,4 | Z1: x3,5 | AA1: x3,6 | AB1: x4,1 | AC1: x4,2 | AD1: x4,3 | AE1: x4,4 | AF1: x4,5 | AG1: x4,6 | AH1: LER | AI1: Sinal | AJ1: LDR
A2: Coeficiente FO | B2: =(Dados!D4) -> 42.5 | C2: =(Dados!D5) -> 45 | D2: =(Dados!D6) -> 47.5 | E2: =(Dados!D7) -> 50 | F2: =(Dados!F4) -> 46.75 | G2: =(Dados!F5) -> 49.5 | H2: =(Dados!F6) -> 52.25 | I2: =(Dados!F7) -> 55 | J2: =Dados!C11 -> 0.1 | K2: =Dados!D11 -> 0.6 | L2: =Dados!E11 -> 0.25 | M2: =Dados!F11 -> 0.8 | N2: =Dados!G11 -> 1.2 | O2: =Dados!H11 -> 0.55 | P2: =Dados!C12 -> 0.5 | Q2: =Dados!D12 -> 0.8 | R2: =Dados!E12 -> 0.05 | S2: =Dados!F12 -> 0.2 | T2: =Dados!G12 -> 0.5 | U2: =Dados!H12 -> 0.75 | V2: =Dados!C13 -> 0.4 | W2: =Dados!D13 -> 0.5 | X2: =Dados!E13 -> 0.7 | Y2: =Dados!F13 -> 0.45 | Z2: =Dados!G13 -> 1 | AA2: =Dados!H13 -> 0.2 | AB2: =Dados!C14 -> 0.7 | AC2: =Dados!D14 -> 0.75 | AD2: =Dados!E14 -> 0.5 | AE2: =Dados!F14 -> 0.85 | AF2: =Dados!G14 -> 0.6 | AG2: =Dados!H14 -> 0.9 | AJ2: =+SUMPRODUCT(B3:AG3,$B$2:$AG$2) -> 20630552 | AL2: LER = Lado Esquerdo da Restrição
A3: Valor da Variável | B3: 200000 | C3: 50000 | D3: 125000 | E3: 10000 | F3: 60000 | G3: 10743 | H3: 0 | I3: 0 | J3: 245000 | K3: 15000 | L3: 0 | M3: 0 | N3: 0 | O3: 0 | P3: 0 | Q3: 0 | R3: 55743 | S3: 0 | T3: 5000 | U3: 0 | V3: 0 | W3: 15000 | X3: 2644 | Y3: 48656 | Z3: 20000 | AA3: 38700 | AB3: 0 | AC3: 0 | AD3: 0 | AE3: 10000 | AF3: 0 | AG3: 0 | AL3: LDR = Lado Direito da Restrição
A4: s1 | B4: 1 | AH4: =+SUMPRODUCT(B4:AG4,$B$3:$AG$3) -> 200000 | AI4: <= | AJ4: ='Variáveis e Restrições'!H6 -> 200000
A5: s2 | C5: 1 | AH5: =+SUMPRODUCT(B5:AG5,$B$3:$AG$3) -> 50000 | AI5: <= | AJ5: ='Variáveis e Restrições'!H7 -> 50000
A6: s3 | D6: 1 | AH6: =+SUMPRODUCT(B6:AG6,$B$3:$AG$3) -> 125000 | AI6: <= | AJ6: ='Variáveis e Restrições'!H8 -> 125000
A7: s4 | E7: 1 | AH7: =+SUMPRODUCT(B7:AG7,$B$3:$AG$3) -> 10000 | AI7: <= | AJ7: ='Variáveis e Restrições'!H9 -> 33500
A8: s5 | F8: 1 | AH8: =+SUMPRODUCT(B8:AG8,$B$3:$AG$3) -> 60000 | AI8: <= | AJ8: ='Variáveis e Restrições'!H10 -> 60000
A9: s6 | G9: 1 | AH9: =+SUMPRODUCT(B9:AG9,$B$3:$AG$3) -> 10743 | AI9: <= | AJ9: ='Variáveis e Restrições'!H11 -> 15000
A10: s7 | H10: 1 | AH10: =+SUMPRODUCT(B10:AG10,$B$3:$AG$3) -> 0 | AI10: <= | AJ10: ='Variáveis e Restrições'!H12 -> 37500
A11: s8 | I11: 1 | AH11: =+SUMPRODUCT(B11:AG11,$B$3:$AG$3) -> 0 | AI11: <= | AJ11: ='Variáveis e Restrições'!H13 -> 10050
A12: s9 | J12: 1 | P12: 1 | V12: 1 | AB12: 1 | AH12: =+SUMPRODUCT(B12:AG12,$B$3:$AG$3) -> 245000 | AI12: >= | AJ12: ='Variáveis e Restrições'!L17 -> 245000
A13: s10 | K13: 1 | Q13: 1 | W13: 1 | AC13: 1 | AH13: =+SUMPRODUCT(B13:AG13,$B$3:$AG$3) -> 30000 | AI13: >= | AJ13: ='Variáveis e Restrições'!L18 -> 30000
A14: s11 | L14: 1 | R14: 1 | X14: 1 | AD14: 1 | AH14: =+SUMPRODUCT(B14:AG14,$B$3:$AG$3) -> 58387 | AI14: >= | AJ14: ='Variáveis e Restrições'!L19 -> 58387
A15: s12 | M15: 1 | S15: 1 | Y15: 1 | AE15: 1 | AH15: =+SUMPRODUCT(B15:AG15,$B$3:$AG$3) -> 58656 | AI15: >= | AJ15: ='Variáveis e Restrições'!L20 -> 58656
A16: s13 | N16: 1 | T16: 1 | Z16: 1 | AF16: 1 | AH16: =+SUMPRODUCT(B16:AG16,$B$3:$AG$3) -> 25000 | AI16: >= | AJ16: ='Variáveis e Restrições'!L21 -> 25000
A17: s14 | O17: 1 | U17: 1 | AA17: 1 | AG17: 1 | AH17: =+SUMPRODUCT(B17:AG17,$B$3:$AG$3) -> 38700 | AI17: >= | AJ17: ='Variáveis e Restrições'!L22 -> 38700
A18: s15 | C18: 1 | G18: 1 | AH18: =+SUMPRODUCT(B18:AG18,$B$3:$AG$3) -> 60743 | AI18: >= | AJ18: ='Variáveis e Restrições'!F26 -> 5000
A19: s16 | T19: 1 | AH19: =+SUMPRODUCT(B19:AG19,$B$3:$AG$3) -> 5000 | AI19: >= | AJ19: ='Variáveis e Restrições'!F27 -> 5000
A20: s17 | L20: -1 | Q20: 1 | AH20: =+SUMPRODUCT(B20:AG20,$B$3:$AG$3) -> 0 | AI20: = | AJ20: 0
A21: s18 | B21: 1 | F21: 1 | AH21: =+SUMPRODUCT(B21:AG21,$B$3:$AG$3) -> 260000 | AI21: >= | AJ21: ='Variáveis e Restrições'!F29 -> 175000
A22: s19 | E22: 1 | I22: 1 | AH22: =+SUMPRODUCT(B22:AG22,$B$3:$AG$3) -> 10000 | AI22: >= | AJ22: ='Variáveis e Restrições'!F30 -> 10000
A23: s20 | AE23: 1 | AH23: =+SUMPRODUCT(B23:AG23,$B$3:$AG$3) -> 10000 | AI23: >= | AJ23: ='Variáveis e Restrições'!F31 -> 10000
A24: s21 | B24: -1 | F24: -1 | J24: 1 | K24: 1 | L24: 1 | M24: 1 | N24: 1 | O24: 1 | AH24: =+SUMPRODUCT(B24:AG24,$B$3:$AG$3) -> 0 | AI24: = | AJ24: 0
A25: s22 | C25: -1 | G25: -1 | P25: 1 | Q25: 1 | R25: 1 | S25: 1 | T25: 1 | U25: 1 | AH25: =+SUMPRODUCT(B25:AG25,$B$3:$AG$3) -> 0 | AI25: = | AJ25: 0
A26: s23 | D26: -1 | H26: -1 | V26: 1 | W26: 1 | X26: 1 | Y26: 1 | Z26: 1 | AA26: 1 | AH26: =+SUMPRODUCT(B26:AG26,$B$3:$AG$3) -> 0 | AI26: = | AJ26: 0
A27: s24 | E27: -1 | I27: -1 | AB27: 1 | AC27: 1 | AD27: 1 | AE27: 1 | AF27: 1 | AG27: 1 | AH27: =+SUMPRODUCT(B27:AG27,$B$3:$AG$3) -> 0 | AI27: = | AJ27: 0

Sheet Relatório de Resposta
A1: Microsoft Excel 16.0 Relatório de Resposta
A2: Folha de Cálculo: [ModDec.xlsx]Modelo0
A3: Relatório Criado: 18/11/2024 12:40:33
A4: Resultado: O Solver encontrou uma solução. Todas as restrições e condições de otimização foram satisfeitas.
A5: Motor do Solver
B6: Motor: LP Simplex
B7: Tempo de Solução: 0,141 Segundos.
B8: Iterações: 40 Subproblemas: 0
A9: Opções do Solver
B10: Tempo Máximo Ilimitado, Iterações Ilimitado, Precision 0,000001
B11: Máximo de Subproblemas Ilimitado, Máximo de Soluções de Número Inteiro 1, Tolerância de Número Inteiro 1%, Assumir NãoNegativo
A14: Célula de Objetivo (Mínimo)
B15: Célula | C15: Nome | D15: Valor Original | E15: Valor Final
B16: $AJ$2 | C16: Coeficiente FO LDR | D16: 20630552 | E16: 20630552
A19: Células de Variável
B20: Célula | C20: Nome | D20: Valor Original | E20: Valor Final | F20: Número inteiro
B21: $B$3 | C21: Valor da Variável x1 | D21: 200000 | E21: 200000 | F21: Contin
B22: $C$3 | C22: Valor da Variável x2 | D22: 50000 | E22: 50000 | F22: Contin
B23: $D$3 | C23: Valor da Variável x3 | D23: 125000 | E23: 125000 | F23: Contin
B24: $E$3 | C24: Valor da Variável x4 | D24: 10000 | E24: 10000 | F24: Contin
B25: $F$3 | C25: Valor da Variável x5 | D25: 60000 | E25: 60000 | F25: Contin
B26: $G$3 | C26: Valor da Variável x6 | D26: 10743 | E26: 10743 | F26: Contin
B27: $H$3 | C27: Valor da Variável x7 | D27: 0 | E27: 0 | F27: Contin
B28: $I$3 | C28: Valor da Variável x8 | D28: 0 | E28: 0 | F28: Contin
B29: $J$3 | C29: Valor da Variável x1,1 | D29: 245000 | E29: 245000 | F29: Contin
B30: $K$3 | C30: Valor da Variável x1,2 | D30: 15000 | E30: 15000 | F30: Contin
B31: $L$3 | C31: Valor da Variável x1,3 | D31: 0 | E31: 0 | F31: Contin
B32: $M$3 | C32: Valor da Variável x1,4 | D32: 0 | E32: 0 | F32: Contin
... B52: $AG$3 | C52: Valor da Variável x4,6 | D52: 0 | E52: 0 | F52: Contin
A55: Restrições
B56: Célula | C56: Nome | D56: Valor da Célula | E56: Fórmula | F56: Estado | G56: Margem
B57: $AH$10 | C57: s7 LER | D57: 0 | E57: $AH$10<=$AJ$10 | F57: Sem Enlace | G57: 37500
B58: $AH$11 | C58: s8 LER | D58: 0 | E58: $AH$11<=$AJ$11 | F58: Sem Enlace | G58: 10050
B59: $AH$12 | C59: s9 LER | D59: 245000 | E59: $AH$12>=$AJ$12 | F59: Enlace | G59: 0
B60: $AH$13 | C60: s10 LER | D60: 30000 | E60: $AH$13>=$AJ$13 | F60: Enlace | G60: 0
B61: $AH$14 | C61: s11 LER | D61: 58387 | E61: $AH$14>=$AJ$14 | F61: Enlace | G61: 0
B62: $AH$15 | C62: s12 LER | D62: 58656 | E62: $AH$15>=$AJ$15 | F62: Enlace | G62: 0
B63: $AH$16 | C63: s13 LER | D63: 25000 | E63: $AH$16>=$AJ$16 | F63: Enlace | G63: 0
B64: $AH$17 | C64: s14 LER | D64: 38700 | E64: $AH$17>=$AJ$17 | F64: Enlace | G64: 0
B65: $AH$18 | C65: s15 LER | D65: 60743 | E65: $AH$18>=$AJ$18 | F65: Sem Enlace | G65: 55743
...

Sheet Relatório de Sensibilidade
A1: Microsoft Excel 16.0 Relatório de Sensibilidade
A2: Folha de Cálculo: [ModDec.xlsx]Modelo0
A3: Relatório Criado: 18/11/2024 12:40:34
A6: Células de Variável
D7: Final | E7: Reduzido | F7: Objetivo | G7: Permissível | H7: Permissível
B8: Célula | C8: Nome | D8: Valor | E8: Custo | F8: Coeficiente | G8: Aumentar | H8: Diminuir
B9: $B$3 | C9: Valor da Variável x1 | D9: 200000 | E9: 0 | F9: 42.5 | G9: 6.25 | H9: 1e+30
B10: $C$3 | C10: Valor da Variável x2 | D10: 50000 | E10: 0 | F10: 45 | G10: 4.5 | H10: 1e+30
B11: $D$3 | C11: Valor da Variável x3 | D11: 125000 | E11: 0 | F11: 47.5 | G11: 1.35 | H11: 1e+30
B12: $E$3 | C12: Valor da Variável x4 | D12: 10000 | E12: 0 | F12: 50 | G12: 5 | H12: 0.75
B13: $F$3 | C13: Valor da Variável x5 | D13: 60000 | E13: 0 | F13: 46.75 | G13: 2 | H13: 1e+30
B14: $G$3 | C14: Valor da Variável x6 | D14: 10743 | E14: 0 | F14: 49.5 | G14: 0.75 | H14: 1.35
B15: $H$3 | C15: Valor da Variável x7 | D15: 0 | E15: 3.4 | F15: 52.25 | G15: 1e+30 | H15: 3.4
B16: $I$3 | C16: Valor da Variável x8 | D16: 0 | E16: 5 | F16: 55 | G16: 1e+30 | H16: 5
B17: $J$3 | C17: Valor da Variável x1,1 | D17: 245000 | E17: 0 | F17: 0.1 | G17: 0.4 | H17: 48.85
B18: $K$3 | C18: Valor da Variável x1,2 | D18: 15000 | E18: 0 | F18: 0.6 | G18: 0.1 | H18: 0.4
B19: $L$3 | C19: Valor da Variável x1,3 | D19: 0 | E19: 0 | F19: 0.25 | G19: 1e+30 | H19: 0.4
B20: $M$3 | C20: Valor da Variável x1,4 | D20: 0 | E20: 0.25 | F20: 0.8 | G20: 1e+30 | H20: 0.25
... B40: $AG$3 | C40: Valor da Variável x4,6 | D40: 0 | E40: 1.1 | F40: 0.9 | G40: 1e+30 | H40: 1.1
A42: Restrições
D43: Final | E43: Sombra | F43: Restrição | G43: Permissível | H43: Permissível
B44: Célula | C44: Nome | D44: Valor | E44: Preço | F44: Lado Direito | G44: Aumentar | H44: Diminuir
B45: $AH$10 | C45: s7 LER | D45: 0 | E45: 0 | F45: 37500 | G45: 1e+30 | H45: 37500
B46: $AH$11 | C46: s8 LER | D46: 0 | E46: 0 | F46: 10050 | G46: 1e+30 | H46: 10050
B47: $AH$12 | C47: s9 LER | D47: 245000 | E47: 48.85 | F47: 245000 | G47: 2644 | H47: 10743
B48: $AH$13 | C48: s10 LER | D48: 30000 | E48: 49.35 | F48: 30000 | G48: 2644 | H48: 10743
B49: $AH$14 | C49: s11 LER | D49: 58387 | E49: 49.55 | F49: 58387 | G49: 4257 | H49: 10743
B50: $AH$15 | C50: s12 LER | D50: 58656 | E50: 49.3 | F50: 58656 | G50: 2644 | H50: 10743
B51: $AH$16 | C51: s13 LER | D51: 25000 | E51: 49.85 | F51: 25000 | G51: 2644 | H51: 10743
B52: $AH$17 | C52: s14 LER | D52: 38700 | E52: 49.05 | F52: 38700 | G52: 2644 | H52: 10743
B53: $AH$18 | C53: s15 LER | D53: 60743 | E53: 0 | F53: 5000 | G53: 55743 | H53: 1e+30
B54: $AH$19 | C54: s16 LER | D54: 5000 | E54: 0.15 | F54: 5000 | G54: 20000 | H54: 2644
B55: $AH$20 | C55: s17 LER | D55: 0 | E55: 0.55 | F55: 0 | G55: 0 | H55: 2644
B56: $AH$21 | C56: s18 LER | D56: 260000 | E56: 0 | F56: 175000 | G56: 85000 | H56: 1e+30
... B68: $AH$9 | C68: s6 LER | D68: 10743 | E68: 0 | F68: 15000 | G68: 1e+30 | H68: 4257

Sheet Relatório de Limites
A1: Microsoft Excel 16.0 Relatório de Limites
A2: Folha de Cálculo: [ModDec.xlsx]Modelo0
A3: Relatório Criado: 18/11/2024 12:40:34
C6: Objetivo
B7: Célula | C7: Nome | D7: Valor
B8: $AJ$2 | C8: Coeficiente FO LDR | D8: 20630552
C11: Variável | F11: Inferior | G11: Objetivo | I11: Superior | J11: Objetivo
B12: Célula | C12: Nome | D12: Valor | F12: Limite | G12: Resultado | I12: Limite | J12: Resultado
B13: $B$3 | C13: Valor da Variável x1 | D13: 200000 | F13: 200000 | G13: 20630552 | I13: 200000 | J13: 20630552
B14: $C$3 | C14: Valor da Variável x2 | D14: 50000 | F14: 50000 | G14: 20630552 | I14: 50000 | J14: 20630552
B15: $D$3 | C15: Valor da Variável x3 | D15: 125000 | F15: 125000 | G15: 20630552 | I15: 125000 | J15: 20630552
B16: $E$3 | C16: Valor da Variável x4 | D16: 10000 | F16: 10000 | G16: 20630552 | I16: 10000 | J16: 20630552
B17: $F$3 | C17: Valor da Variável x5 | D17: 60000 | F17: 60000 | G17: 20630552 | I17: 60000 | J17: 20630552
B18: $G$3 | C18: Valor da Variável x6 | D18: 10743 | F18: 10743 | G18: 20630552 | I18: 10743 | J18: 20630552
B19: $H$3 | C19: Valor da Variável x7 | D19: 0 | F19: 0 | G19: 20630552 | I19: 0 | J19: 20630552
B20: $I$3 | C20: Valor da Variável x8 | D20: 0 | F20: 0 | G20: 20630552 | I20: 0 | J20: 20630552
B21: $J$3 | C21: Valor da Variável x1,1 | D21: 245000 | F21: 245000 | G21: 20630552 | I21: 245000 | J21: 20630552
B22: $K$3 | C22: Valor da Variável x1,2 | D22: 15000 | F22: 15000 | G22: 20630552 | I22: 15000 | J22: 20630552
B23: $L$3 | C23: Valor da Variável x1,3 | D23: 0 | F23: 0 | G23: 20630552 | I23: 0 | J23: 20630552
B24: $M$3 | C24: Valor da Variável x1,4 | D24: 0 | F24: 0 | G24: 20630552 | I24: 0 | J24: 20630552
... B44: $AG$3 | C44: Valor da Variável x4,6 | D44: 0 | F44: 0 | G44: 20630552 | I44: 0 | J44: 20630552
